Workbook

Sheet Simple Dashboard
A1: SIMPLE DASHBOARD
A3: THIS MONTH — PACE
A4: Month | B4: =TEXT(TODAY(),"MMMM YYYY") -> August 2026 | C4: Days left | D4: =EOMONTH(TODAY(),0)-TODAY()+1 -> 25
A5: Budget remaining | B5: ='Monthly Budget'!B9 -> 6259.67 | C5: Safe to spend / day | D5: =IF(D4<=0,0,MAX(0,B5)/D4) -> 250.3868
A6: Budget used % | B6: ='Monthly Budget'!B16 -> 0.79807516 | C6: Month elapsed % | D6: =DAY(TODAY())/DAY(EOMONTH(TODAY(),0)) -> 0.22580645
A7: Pace check | B7: =IF(B5<0,"OVER BUDGET — stop discretionary spend",IF(B6>D6+0.05,"Spending faster than the month — slow down",IF(B6>D6,"Slightly ahead of pace — be careful","On track"))) -> Spending faster than the month — slow down
A9: UPCOMING CREDIT CARD BILLS
A10: HDFC Credit Card | B10: =Configuration!C15+SUMIF(Ledger!$H:$H,"HDFC Credit Card",Ledger!$G:$G)-SUMIF(Ledger!$I:$I,"HDFC Credit Card",Ledger!$G:$G) -> 32765.33
A11: ICICI Credit Card | B11: =Configuration!C16+SUMIF(Ledger!$H:$H,"ICICI Credit Card",Ledger!$G:$G)-SUMIF(Ledger!$I:$I,"ICICI Credit Card",Ledger!$G:$G) -> 3795.04
A12: Total CC due | B12: =B10+B11 -> 36560.37
A14: FREE TO ALLOCATE — emergency · invest · goals
A15: Total liquid savings | B15: =Reconciliation!C5+Reconciliation!C6+Reconciliation!C7+Reconciliation!C8 -> 47791.56 | C15: savings + cash + wallets
A16: Budget still reserved | B16: =MAX(0,B5) -> 6259.67 | C16: money still needed for this month's budget
A17: Free to allocate | B17: =B15-B16 -> 41531.89 | C17: total savings − budget remaining
A19: NEXT MONTH FREE-TO-ALLOCATE — estimate
A20: Free to allocate (today) | B20: =B17 -> 41531.89 | C20: starting point
A21: − Pay all CC dues | B21: =B12 -> 36560.37 | C21: after clearing upcoming bills
A22: + Monthly salary | B22: =Configuration!B7 -> 83000 | C22: from Configuration (edit yellow cell)
A23: − Next month budget | B23: =IFERROR(INDEX('Monthly Budget'!$B$20:$B$61,MATCH(EDATE(DATE(YEAR(TODAY()),MONTH(TODAY()),1),1),'Monthly Budget'!$A$20:$A$61,0)),Configuration!B6) -> 31000 | C23: reserved for next month's spend cap
A24: Est. free next month | B24: =B20-B21+B22-B23 -> 56971.52 | C24: potential surplus after CC + budget + salary
A25: Estimate = free-to-allocate today − CC dues + monthly salary − next month's budget. Assumes you finish this month's remaining budget and pay full CC dues. If this month's salary is already in liquid savings, it is already counted — use Configuration monthly salary as take-home you expect to receive for the next cycle.

Sheet Detailed Dashboard
A1: DETAILED DASHBOARD
A2: Full snapshot + charts. Day-to-day numbers live on Simple Dashboard. Reload after phone saves.
A4: PACE — BE CAREFUL | H4: CHART DATA
A5: Month | B5: =TEXT(TODAY(),"MMMM YYYY") -> August 2026 | C5: Days left in month | D5: =EOMONTH(TODAY(),0)-TODAY()+1 -> 25 | E5: Days elapsed | F5: =DAY(TODAY()) -> 7 | H5: Budget slice | I5: Amount
A6: Monthly Budget | B6: ='Monthly Budget'!B6 -> 31000 | C6: Budget remaining | D6: ='Monthly Budget'!B9 -> 6259.67 | E6: Budget spent | F6: ='Monthly Budget'!B8 -> 24740.33 | H6: Spent | I6: =MAX(0,F6) -> 24740.33
A7: Safe to spend / day left | B7: =IF(D5<=0,0,MAX(0,D6)/D5) -> 250.3868 | C7: Budget used % | D7: ='Monthly Budget'!B16 -> 0.79807516 | E7: Month elapsed % | F7: =DAY(TODAY())/DAY(EOMONTH(TODAY(),0)) -> 0.22580645 | H7: Remaining | I7: =MAX(0,D6) -> 6259.67
A8: Pace check | B8: =IF(D6<0,"OVER BUDGET — stop discretionary spend",IF(D7>F7+0.05,"Spending faster than the month — slow down",IF(D7>F7,"Slightly ahead of pace — be careful","On track"))) -> Spending faster than the month — slow down | H8: (Over budget ignored in pie; see pace check)
A9: Tip: Safe ₹/day = budget remaining ÷ days left (including today). If used % is above month elapsed %, you are burning budget too fast.
H10: Last 6 months
A11: THIS MONTH | D11: UPCOMING CREDIT CARD BILLS | H11: Month | I11: Income | J11: Budget Exp
A12: Income | B12: ='Monthly Budget'!B7 -> 83167 | D12: HDFC Credit Card | H12: =TEXT(EDATE(DATE(YEAR(TODAY()),MONTH(TODAY()),1),-5),"mmm yy") -> Mar 26 | I12: =SUMIFS(Ledger!$G:$G,Ledger!$D:$D,TEXT(EDATE(DATE(YEAR(TODAY()),MONTH(TODAY()),1),-5),"MMMM"),Ledger!$E:$E,YEAR(EDATE(DATE(YEAR(TODAY()),MONTH(TODAY()),1),-5)),Ledger!$F:$F,"Income") -> 0 | J12: =SUMIFS(Ledger!$G:$G,Ledger!$D:$D,TEXT(EDATE(DATE(YEAR(TODAY()),MONTH(TODAY()),1),-5),"MMMM"),Ledger!$E:$E,YEAR(EDATE(DATE(YEAR(TODAY()),MONTH(TODAY()),1),-5)),Ledger!$F:$F,"Expense",Ledger!$K:$K,TRUE())-SUMIFS(Ledger!$G:$G,Ledger!$D:$D,TEXT(EDATE(DATE(YEAR(TODAY()),MONTH(TODAY()),1),-5),"MMMM"),Ledger!$E:$E,YEAR(EDATE(DATE(YEAR(TODAY()),MONTH(TODAY()),1),-5)),Ledger!$F:$F,"Refund",Ledger!$K:$K,TRUE()) -> 0
A13: Budget Expenses | B13: ='Monthly Budget'!B8 -> 24740.33 | D13: Outstanding | E13: =Configuration!C15+SUMIF(Ledger!$H:$H,"HDFC Credit Card",Ledger!$G:$G)-SUMIF(Ledger!$I:$I,"HDFC Credit Card",Ledger!$G:$G) -> 32765.33 | H13: =TEXT(EDATE(DATE(YEAR(TODAY()),MONTH(TODAY()),1),-4),"mmm yy") -> Apr 26 | I13: =SUMIFS(Ledger!$G:$G,Ledger!$D:$D,TEXT(EDATE(DATE(YEAR(TODAY()),MONTH(TODAY()),1),-4),"MMMM"),Ledger!$E:$E,YEAR(EDATE(DATE(YEAR(TODAY()),MONTH(TODAY()),1),-4)),Ledger!$F:$F,"Income") -> 0 | J13: =SUMIFS(Ledger!$G:$G,Ledger!$D:$D,TEXT(EDATE(DATE(YEAR(TODAY()),MONTH(TODAY()),1),-4),"MMMM"),Ledger!$E:$E,YEAR(EDATE(DATE(YEAR(TODAY()),MONTH(TODAY()),1),-4)),Ledger!$F:$F,"Expense",Ledger!$K:$K,TRUE())-SUMIFS(Ledger!$G:$G,Ledger!$D:$D,TEXT(EDATE(DATE(YEAR(TODAY()),MONTH(TODAY()),1),-4),"MMMM"),Ledger!$E:$E,YEAR(EDATE(DATE(YEAR(TODAY()),MONTH(TODAY()),1),-4)),Ledger!$F:$F,"Refund",Ledger!$K:$K,TRUE()) -> 0
A14: Non-Budget Expenses | B14: ='Monthly Budget'!B10 -> 50671 | D14: Limit / Available | E14: =Configuration!D15 -> 396000 | F14: =E14-E13 -> 363234.67 | H14: =TEXT(EDATE(DATE(YEAR(TODAY()),MONTH(TODAY()),1),-3),"mmm yy") -> May 26 | I14: =SUMIFS(Ledger!$G:$G,Ledger!$D:$D,TEXT(EDATE(DATE(YEAR(TODAY()),MONTH(TODAY()),1),-3),"MMMM"),Ledger!$E:$E,YEAR(EDATE(DATE(YEAR(TODAY()),MONTH(TODAY()),1),-3)),Ledger!$F:$F,"Income") -> 0 | J14: =SUMIFS(Ledger!$G:$G,Ledger!$D:$D,TEXT(EDATE(DATE(YEAR(TODAY()),MONTH(TODAY()),1),-3),"MMMM"),Ledger!$E:$E,YEAR(EDATE(DATE(YEAR(TODAY()),MONTH(TODAY()),1),-3)),Ledger!$F:$F,"Expense",Ledger!$K:$K,TRUE())-SUMIFS(Ledger!$G:$G,Ledger!$D:$D,TEXT(EDATE(DATE(YEAR(TODAY()),MONTH(TODAY()),1),-3),"MMMM"),Ledger!$E:$E,YEAR(EDATE(DATE(YEAR(TODAY()),MONTH(TODAY()),1),-3)),Ledger!$F:$F,"Refund",Ledger!$K:$K,TRUE()) -> 0
A15: Est. Savings | B15: ='Monthly Budget'!B15 -> 7755.67 | D15: Utilization | E15: =IF(E14=0,0,E13/E14) -> 0.082740732 | H15: =TEXT(EDATE(DATE(YEAR(TODAY()),MONTH(TODAY()),1),-2),"mmm yy") -> Jun 26 | I15: =SUMIFS(Ledger!$G:$G,Ledger!$D:$D,TEXT(EDATE(DATE(YEAR(TODAY()),MONTH(TODAY()),1),-2),"MMMM"),Ledger!$E:$E,YEAR(EDATE(DATE(YEAR(TODAY()),MONTH(TODAY()),1),-2)),Ledger!$F:$F,"Income") -> 0 | J15: =SUMIFS(Ledger!$G:$G,Ledger!$D:$D,TEXT(EDATE(DATE(YEAR(TODAY()),MONTH(TODAY()),1),-2),"MMMM"),Ledger!$E:$E,YEAR(EDATE(DATE(YEAR(TODAY()),MONTH(TODAY()),1),-2)),Ledger!$F:$F,"Expense",Ledger!$K:$K,TRUE())-SUMIFS(Ledger!$G:$G,Ledger!$D:$D,TEXT(EDATE(DATE(YEAR(TODAY()),MONTH(TODAY()),1),-2),"MMMM"),Ledger!$E:$E,YEAR(EDATE(DATE(YEAR(TODAY()),MONTH(TODAY()),1),-2)),Ledger!$F:$F,"Refund",Ledger!$K:$K,TRUE()) -> 0
A16: Investments | B16: ='Monthly Budget'!B11 -> 0 | D16: ICICI Credit Card | H16: =TEXT(EDATE(DATE(YEAR(TODAY()),MONTH(TODAY()),1),-1),"mmm yy") -> Jul 26 | I16: =SUMIFS(Ledger!$G:$G,Ledger!$D:$D,TEXT(EDATE(DATE(YEAR(TODAY()),MONTH(TODAY()),1),-1),"MMMM"),Ledger!$E:$E,YEAR(EDATE(DATE(YEAR(TODAY()),MONTH(TODAY()),1),-1)),Ledger!$F:$F,"Income") -> 0 | J16: =SUMIFS(Ledger!$G:$G,Ledger!$D:$D,TEXT(EDATE(DATE(YEAR(TODAY()),MONTH(TODAY()),1),-1),"MMMM"),Ledger!$E:$E,YEAR(EDATE(DATE(YEAR(TODAY()),MONTH(TODAY()),1),-1)),Ledger!$F:$F,"Expense",Ledger!$K:$K,TRUE())-SUMIFS(Ledger!$G:$G,Ledger!$D:$D,TEXT(EDATE(DATE(YEAR(TODAY()),MONTH(TODAY()),1),-1),"MMMM"),Ledger!$E:$E,YEAR(EDATE(DATE(YEAR(TODAY()),MONTH(TODAY()),1),-1)),Ledger!$F:$F,"Refund",Ledger!$K:$K,TRUE()) -> 3795.04
A17: EMIs + Rent | B17: ='Monthly Budget'!B12+'Monthly Budget'!B13 -> 10800 | D17: Outstanding | E17: =Configuration!C16+SUMIF(Ledger!$H:$H,"ICICI Credit Card",Ledger!$G:$G)-SUMIF(Ledger!$I:$I,"ICICI Credit Card",Ledger!$G:$G) -> 3795.04 | H17: =TEXT(EDATE(DATE(YEAR(TODAY()),MONTH(TODAY()),1),0),"mmm yy") -> Aug 26 | I17: =SUMIFS(Ledger!$G:$G,Ledger!$D:$D,TEXT(EDATE(DATE(YEAR(TODAY()),MONTH(TODAY()),1),0),"MMMM"),Ledger!$E:$E,YEAR(EDATE(DATE(YEAR(TODAY()),MONTH(TODAY()),1),0)),Ledger!$F:$F,"Income") -> 83167 | J17: =SUMIFS(Ledger!$G:$G,Ledger!$D:$D,TEXT(EDATE(DATE(YEAR(TODAY()),MONTH(TODAY()),1),0),"MMMM"),Ledger!$E:$E,YEAR(EDATE(DATE(YEAR(TODAY()),MONTH(TODAY()),1),0)),Ledger!$F:$F,"Expense",Ledger!$K:$K,TRUE())-SUMIFS(Ledger!$G:$G,Ledger!$D:$D,TEXT(EDATE(DATE(YEAR(TODAY()),MONTH(TODAY()),1),0),"MMMM"),Ledger!$E:$E,YEAR(EDATE(DATE(YEAR(TODAY()),MONTH(TODAY()),1),0)),Ledger!$F:$F,"Refund",Ledger!$K:$K,TRUE()) -> 24740.33
D18: Limit / Available | E18: =Configuration!D16 -> 100000 | F18: =E18-E17 -> 96204.96
A19: FREE TO ALLOCATE — emergency · invest · goals | D19: Utilization | E19: =IF(E18=0,0,E17/E18) -> 0.0379504 | H19: Spend by category (this month)
A20: Total liquid savings | B20: =Reconciliation!C5+Reconciliation!C6+Reconciliation!C7+Reconciliation!C8 -> 47791.56 | D20: Total CC due | E20: =E13+E17 -> 36560.37 | H20: Category | I20: Spent
A21: Budget still reserved | B21: =MAX(0,D6) -> 6259.67 | H21: Groceries - Online | I21: =SUMIFS(Ledger!$G:$G,Ledger!$D:$D,TEXT(TODAY(),"MMMM"),Ledger!$E:$E,YEAR(TODAY()),Ledger!$F:$F,"Expense",Ledger!$J:$J,H21)-SUMIFS(Ledger!$G:$G,Ledger!$D:$D,TEXT(TODAY(),"MMMM"),Ledger!$E:$E,YEAR(TODAY()),Ledger!$F:$F,"Refund",Ledger!$J:$J,H21) -> 1069
A22: Free to allocate | B22: =B20-B21 -> 41531.89 | D22: NEXT MONTH FREE-TO-ALLOCATE — estimate | H22: Groceries - Physical | I22: =SUMIFS(Ledger!$G:$G,Ledger!$D:$D,TEXT(TODAY(),"MMMM"),Ledger!$E:$E,YEAR(TODAY()),Ledger!$F:$F,"Expense",Ledger!$J:$J,H22)-SUMIFS(Ledger!$G:$G,Ledger!$D:$D,TEXT(TODAY(),"MMMM"),Ledger!$E:$E,YEAR(TODAY()),Ledger!$F:$F,"Refund",Ledger!$J:$J,H22) -> 280
A23: Free to allocate = liquid − budget remaining (does not subtract CC). Next-month estimate = free today − CC dues + salary − next budget. Set Monthly Salary on Configuration. | D23: Free to allocate (today) | E23: =B22 -> 41531.89 | H23: Eating outside | I23: =SUMIFS(Ledger!$G:$G,Ledger!$D:$D,TEXT(TODAY(),"MMMM"),Ledger!$E:$E,YEAR(TODAY()),Ledger!$F:$F,"Expense",Ledger!$J:$J,H23)-SUMIFS(Ledger!$G:$G,Ledger!$D:$D,TEXT(TODAY(),"MMMM"),Ledger!$E:$E,YEAR(TODAY()),Ledger!$F:$F,"Refund",Ledger!$J:$J,H23) -> 1028.33
D24: − Pay all CC dues | E24: =E20 -> 36560.37 | H24: Food delivery | I24: =SUMIFS(Ledger!$G:$G,Ledger!$D:$D,TEXT(TODAY(),"MMMM"),Ledger!$E:$E,YEAR(TODAY()),Ledger!$F:$F,"Expense",Ledger!$J:$J,H24)-SUMIFS(Ledger!$G:$G,Ledger!$D:$D,TEXT(TODAY(),"MMMM"),Ledger!$E:$E,YEAR(TODAY()),Ledger!$F:$F,"Refund",Ledger!$J:$J,H24) -> 0
D25: + Monthly salary | E25: =Configuration!B7 -> 83000 | H25: Cafe / Snacks | I25: =SUMIFS(Ledger!$G:$G,Ledger!$D:$D,TEXT(TODAY(),"MMMM"),Ledger!$E:$E,YEAR(TODAY()),Ledger!$F:$F,"Expense",Ledger!$J:$J,H25)-SUMIFS(Ledger!$G:$G,Ledger!$D:$D,TEXT(TODAY(),"MMMM"),Ledger!$E:$E,YEAR(TODAY()),Ledger!$F:$F,"Refund",Ledger!$J:$J,H25) -> 0
D26: − Next month budget | E26: =IFERROR(INDEX('Monthly Budget'!$B$20:$B$61,MATCH(EDATE(DATE(YEAR(TODAY()),MONTH(TODAY()),1),1),'Monthly Budget'!$A$20:$A$61,0)),Configuration!B6) -> 31000 | H26: Petrol | I26: =SUMIFS(Ledger!$G:$G,Ledger!$D:$D,TEXT(TODAY(),"MMMM"),Ledger!$E:$E,YEAR(TODAY()),Ledger!$F:$F,"Expense",Ledger!$J:$J,H26)-SUMIFS(Ledger!$G:$G,Ledger!$D:$D,TEXT(TODAY(),"MMMM"),Ledger!$E:$E,YEAR(TODAY()),Ledger!$F:$F,"Refund",Ledger!$J:$J,H26) -> 0
D27: Est. free next month | E27: =E23-E24+E25-E26 -> 56971.52 | H27: Cab / Auto | I27: =SUMIFS(Ledger!$G:$G,Ledger!$D:$D,TEXT(TODAY(),"MMMM"),Ledger!$E:$E,YEAR(TODAY()),Ledger!$F:$F,"Expense",Ledger!$J:$J,H27)-SUMIFS(Ledger!$G:$G,Ledger!$D:$D,TEXT(TODAY(),"MMMM"),Ledger!$E:$E,YEAR(TODAY()),Ledger!$F:$F,"Refund",Ledger!$J:$J,H27) -> 0
H28: Salon | I28: =SUMIFS(Ledger!$G:$G,Ledger!$D:$D,TEXT(TODAY(),"MMMM"),Ledger!$E:$E,YEAR(TODAY()),Ledger!$F:$F,"Expense",Ledger!$J:$J,H28)-SUMIFS(Ledger!$G:$G,Ledger!$D:$D,TEXT(TODAY(),"MMMM"),Ledger!$E:$E,YEAR(TODAY()),Ledger!$F:$F,"Refund",Ledger!$J:$J,H28) -> 0
A29: ACCOUNT BALANCES | D29: NET WORTH | H29: Subscription | I29: =SUMIFS(Ledger!$G:$G,Ledger!$D:$D,TEXT(TODAY(),"MMMM"),Ledger!$E:$E,YEAR(TODAY()),Ledger!$F:$F,"Expense",Ledger!$J:$J,H29)-SUMIFS(Ledger!$G:$G,Ledger!$D:$D,TEXT(TODAY(),"MMMM"),Ledger!$E:$E,YEAR(TODAY()),Ledger!$F:$F,"Refund",Ledger!$J:$J,H29) -> 0
A30: Account | B30: Balance / Due | D30: Savings & Cash | E30: =Reconciliation!C5+Reconciliation!C6+Reconciliation!C7+Reconciliation!C8 -> 47791.56 | H30: Electricity bill | I30: =SUMIFS(Ledger!$G:$G,Ledger!$D:$D,TEXT(TODAY(),"MMMM"),Ledger!$E:$E,YEAR(TODAY()),Ledger!$F:$F,"Expense",Ledger!$J:$J,H30)-SUMIFS(Ledger!$G:$G,Ledger!$D:$D,TEXT(TODAY(),"MMMM"),Ledger!$E:$E,YEAR(TODAY()),Ledger!$F:$F,"Refund",Ledger!$J:$J,H30) -> 0
A31: =Reconciliation!A5 -> HDFC Savings | B31: =Reconciliation!C5 -> 47649.45 | D31: FD | E31: =Reconciliation!C11 -> 0 | H31: House cleaning (UC) | I31: =SUMIFS(Ledger!$G:$G,Ledger!$D:$D,TEXT(TODAY(),"MMMM"),Ledger!$E:$E,YEAR(TODAY()),Ledger!$F:$F,"Expense",Ledger!$J:$J,H31)-SUMIFS(Ledger!$G:$G,Ledger!$D:$D,TEXT(TODAY(),"MMMM"),Ledger!$E:$E,YEAR(TODAY()),Ledger!$F:$F,"Refund",Ledger!$J:$J,H31) -> 270
A32: =Reconciliation!A6 -> ICICI Savings | B32: =Reconciliation!C6 -> 142.11 | D32: Investments (MF) | E32: =Reconciliation!C12 -> 0 | H32: Shopping - Online | I32: =SUMIFS(Ledger!$G:$G,Ledger!$D:$D,TEXT(TODAY(),"MMMM"),Ledger!$E:$E,YEAR(TODAY()),Ledger!$F:$F,"Expense",Ledger!$J:$J,H32)-SUMIFS(Ledger!$G:$G,Ledger!$D:$D,TEXT(TODAY(),"MMMM"),Ledger!$E:$E,YEAR(TODAY()),Ledger!$F:$F,"Refund",Ledger!$J:$J,H32) -> 0
A33: =Reconciliation!A7 -> Cash | B33: =Reconciliation!C7 -> 0 | D33: Total Assets | E33: =E30+E31+E32 -> 47791.56 | H33: Entertainment | I33: =SUMIFS(Ledger!$G:$G,Ledger!$D:$D,TEXT(TODAY(),"MMMM"),Ledger!$E:$E,YEAR(TODAY()),Ledger!$F:$F,"Expense",Ledger!$J:$J,H33)-SUMIFS(Ledger!$G:$G,Ledger!$D:$D,TEXT(TODAY(),"MMMM"),Ledger!$E:$E,YEAR(TODAY()),Ledger!$F:$F,"Refund",Ledger!$J:$J,H33) -> 899
A34: =Reconciliation!A8 -> Wallet | B34: =Reconciliation!C8 -> 0 | D34: Credit Card Due | E34: =Reconciliation!C9+Reconciliation!C10 -> 36560.37 | H34: Medical | I34: =SUMIFS(Ledger!$G:$G,Ledger!$D:$D,TEXT(TODAY(),"MMMM"),Ledger!$E:$E,YEAR(TODAY()),Ledger!$F:$F,"Expense",Ledger!$J:$J,H34)-SUMIFS(Ledger!$G:$G,Ledger!$D:$D,TEXT(TODAY(),"MMMM"),Ledger!$E:$E,YEAR(TODAY()),Ledger!$F:$F,"Refund",Ledger!$J:$J,H34) -> 5
A35: =Reconciliation!A9 -> HDFC Credit Card | B35: =Reconciliation!C9 -> 32765.33 | D35: NET WORTH | E35: =E33-E34 -> 11231.19 | H35: Other | I35: =SUMIFS(Ledger!$G:$G,Ledger!$D:$D,TEXT(TODAY(),"MMMM"),Ledger!$E:$E,YEAR(TODAY()),Ledger!$F:$F,"Expense",Ledger!$J:$J,H35)-SUMIFS(Ledger!$G:$G,Ledger!$D:$D,TEXT(TODAY(),"MMMM"),Ledger!$E:$E,YEAR(TODAY()),Ledger!$F:$F,"Refund",Ledger!$J:$J,H35) -> 135
A36: =Reconciliation!A10 -> ICICI Credit Card | B36: =Reconciliation!C10 -> 3795.04
A37: =Reconciliation!A11 -> FD | B37: =Reconciliation!C11 -> 0
A38: =Reconciliation!A12 -> Mutual Fund | B38: =Reconciliation!C12 -> 0
A39: =Reconciliation!A13 -> Employer | B39: =Reconciliation!C13 -> -83167
A40: =Reconciliation!A14 -> Expense | B40: =Reconciliation!C14 -> 64206.37
A41: =Reconciliation!A15 -> External | B41: =Reconciliation!C15 -> 0
...

Sheet Ledger
A1: Date | B1: Time | C1: Day | D1: Month | E1: Year | F1: Type | G1: Amount (₹) | H1: From Account | I1: To Account | J1: Category | K1: Include in Budget | L1: Notes | M1: Source
A2: 46228 | C2: =IF(A2="","",TEXT(A2,"dddd")) -> Saturday | D2: =IF(A2="","",TEXT(A2,"MMMM")) -> July | E2: =IF(A2="","",YEAR(A2)) -> 2026 | F2: Expense | G2: 2817 | H2: ICICI Credit Card | I2: Expense | J2: Electricity bill | K2: =TRUE() -> TRUE | L2: UK power bill
A3: 46229 | C3: =IF(A3="","",TEXT(A3,"dddd")) -> Sunday | D3: =IF(A3="","",TEXT(A3,"MMMM")) -> July | E3: =IF(A3="","",YEAR(A3)) -> 2026 | F3: Expense | G3: 123 | H3: ICICI Credit Card | I3: Expense | J3: Eating outside | K3: =TRUE() -> TRUE | L3: Swiggy food
A4: 46230 | C4: =IF(A4="","",TEXT(A4,"dddd")) -> Monday | D4: =IF(A4="","",TEXT(A4,"MMMM")) -> July | E4: =IF(A4="","",YEAR(A4)) -> 2026 | F4: Expense | G4: 142 | H4: ICICI Credit Card | I4: Expense | J4: Eating outside | K4: =TRUE() -> TRUE | L4: Swiggy food
A5: 46232 | C5: =IF(A5="","",TEXT(A5,"dddd")) -> Wednesday | D5: =IF(A5="","",TEXT(A5,"MMMM")) -> July | E5: =IF(A5="","",YEAR(A5)) -> 2026 | F5: Expense | G5: 140 | H5: ICICI Credit Card | I5: Expense | J5: Eating outside | K5: =TRUE() -> TRUE | L5: Swiggy food
A6: 46232 | C6: =IF(A6="","",TEXT(A6,"dddd")) -> Wednesday | D6: =IF(A6="","",TEXT(A6,"MMMM")) -> July | E6: =IF(A6="","",YEAR(A6)) -> 2026 | F6: Refund | G6: 140 | H6: Expense | I6: ICICI Credit Card | J6: Refund | K6: =TRUE() -> TRUE | L6: Swiggy refund
A7: 46232 | C7: =IF(A7="","",TEXT(A7,"dddd")) -> Wednesday | D7: =IF(A7="","",TEXT(A7,"MMMM")) -> July | E7: =IF(A7="","",YEAR(A7)) -> 2026 | F7: Expense | G7: 216 | H7: ICICI Credit Card | I7: Expense | J7: Eating outside | K7: =TRUE() -> TRUE | L7: Swiggy food
A8: 46233 | C8: =IF(A8="","",TEXT(A8,"dddd")) -> Thursday | D8: =IF(A8="","",TEXT(A8,"MMMM")) -> July | E8: =IF(A8="","",YEAR(A8)) -> 2026 | F8: Expense | G8: 169 | H8: ICICI Credit Card | I8: Expense | J8: Eating outside | K8: =TRUE() -> TRUE | L8: Swiggy food
A9: 46233 | C9: =IF(A9="","",TEXT(A9,"dddd")) -> Thursday | D9: =IF(A9="","",TEXT(A9,"MMMM")) -> July | E9: =IF(A9="","",YEAR(A9)) -> 2026 | F9: Expense | G9: 328.04 | H9: ICICI Credit Card | I9: Expense | J9: Entertainment | K9: =TRUE() -> TRUE | L9: BookMyShow
A10: 46235 | C10: =IF(A10="","",TEXT(A10,"dddd")) -> Saturday | D10: =IF(A10="","",TEXT(A10,"MMMM")) -> August | E10: =IF(A10="","",YEAR(A10)) -> 2026 | F10: Income | G10: 83167 | H10: Employer | I10: HDFC Savings | J10: Salary | K10: =FALSE() -> FALSE | L10: Aug salary credit
A11: 46235 | C11: =IF(A11="","",TEXT(A11,"dddd")) -> Saturday | D11: =IF(A11="","",TEXT(A11,"MMMM")) -> August | E11: =IF(A11="","",YEAR(A11)) -> 2026 | F11: Expense | G11: 20 | H11: HDFC Savings | I11: Expense | J11: Eating outside | K11: =TRUE() -> TRUE | L11: Local tea snack
A12: 46235 | C12: =IF(A12="","",TEXT(A12,"dddd")) -> Saturday | D12: =IF(A12="","",TEXT(A12,"MMMM")) -> August | E12: =IF(A12="","",YEAR(A12)) -> 2026 | F12: Expense | G12: 25 | H12: HDFC Savings | I12: Expense | J12: Eating outside | K12: =TRUE() -> TRUE | L12: Protein Hub
A13: 46235 | C13: =IF(A13="","",TEXT(A13,"dddd")) -> Saturday | D13: =IF(A13="","",TEXT(A13,"MMMM")) -> August | E13: =IF(A13="","",YEAR(A13)) -> 2026 | F13: Expense | G13: 30 | H13: HDFC Savings | I13: Expense | J13: Groceries - Physical | K13: =TRUE() -> TRUE | L13: Value Mart
A14: 46235 | C14: =IF(A14="","",TEXT(A14,"dddd")) -> Saturday | D14: =IF(A14="","",TEXT(A14,"MMMM")) -> August | E14: =IF(A14="","",YEAR(A14)) -> 2026 | F14: Expense | G14: 60 | H14: HDFC Savings | I14: Expense | J14: Groceries - Physical | K14: =TRUE() -> TRUE | L14: Value Mart
A15: 46235 | C15: =IF(A15="","",TEXT(A15,"dddd")) -> Saturday | D15: =IF(A15="","",TEXT(A15,"MMMM")) -> August | E15: =IF(A15="","",YEAR(A15)) -> 2026 | F15: Expense | G15: 84 | H15: HDFC Credit Card | I15: Expense | J15: House cleaning (UC) | K15: =TRUE() -> TRUE | L15: Urban Company
A16: 46235 | C16: =IF(A16="","",TEXT(A16,"dddd")) -> Saturday | D16: =IF(A16="","",TEXT(A16,"MMMM")) -> August | E16: =IF(A16="","",YEAR(A16)) -> 2026 | F16: Expense | G16: 278 | H16: HDFC Credit Card | I16: Expense | J16: Groceries - Online | K16: =TRUE() -> TRUE | L16: Zepto groceries
A17: 46235 | C17: =IF(A17="","",TEXT(A17,"dddd")) -> Saturday | D17: =IF(A17="","",TEXT(A17,"MMMM")) -> August | E17: =IF(A17="","",YEAR(A17)) -> 2026 | F17: Expense | G17: 285.33 | H17: HDFC Credit Card | I17: Expense | J17: Eating outside | K17: =TRUE() -> TRUE | L17: Zomato food
A18: 46235 | C18: =IF(A18="","",TEXT(A18,"dddd")) -> Saturday | D18: =IF(A18="","",TEXT(A18,"MMMM")) -> August | E18: =IF(A18="","",YEAR(A18)) -> 2026 | F18: Expense | G18: 10000 | H18: HDFC Savings | I18: Expense | J18: Family Expense | K18: =TRUE() -> TRUE | L18: Monthly to dad
A19: 46235 | C19: =IF(A19="","",TEXT(A19,"dddd")) -> Saturday | D19: =IF(A19="","",TEXT(A19,"MMMM")) -> August | E19: =IF(A19="","",YEAR(A19)) -> 2026 | F19: Expense | G19: 10800 | H19: HDFC Savings | I19: Expense | J19: Rent | K19: =TRUE() -> TRUE | L19: Monthly rent
A20: 46235 | C20: =IF(A20="","",TEXT(A20,"dddd")) -> Saturday | D20: =IF(A20="","",TEXT(A20,"MMMM")) -> August | E20: =IF(A20="","",YEAR(A20)) -> 2026 | F20: Credit Card Payment | G20: 11723.51 | H20: HDFC Savings | I20: ICICI Credit Card | J20: Credit Card Bill | K20: =FALSE() -> FALSE | L20: ICICI CC bill
A21: 46235 | C21: =IF(A21="","",TEXT(A21,"dddd")) -> Saturday | D21: =IF(A21="","",TEXT(A21,"MMMM")) -> August | E21: =IF(A21="","",YEAR(A21)) -> 2026 | F21: Expense | G21: 20800 | H21: HDFC Savings | I21: Expense | J21: Transfer | K21: =FALSE() -> FALSE | L21: To Hency Patel
A22: 46235 | C22: =IF(A22="","",TEXT(A22,"dddd")) -> Saturday | D22: =IF(A22="","",TEXT(A22,"MMMM")) -> August | E22: =IF(A22="","",YEAR(A22)) -> 2026 | F22: Expense | G22: 29871 | H22: HDFC Credit Card | I22: Expense | J22: Travel / Flight | K22: =FALSE() -> FALSE | L22: IndiGo flight – mansi & mummy flight to hyd for 1 week, rakshabandhan. Round trip
A23: 46236 | C23: =IF(A23="","",TEXT(A23,"dddd")) -> Sunday | D23: =IF(A23="","",TEXT(A23,"MMMM")) -> August | E23: =IF(A23="","",YEAR(A23)) -> 2026 | F23: Expense | G23: 23 | H23: HDFC Savings | I23: Expense | J23: Groceries - Physical | K23: =TRUE() -> TRUE | L23: Akshayakalpa milk
A24: 46236 | C24: =IF(A24="","",TEXT(A24,"dddd")) -> Sunday | D24: =IF(A24="","",TEXT(A24,"MMMM")) -> August | E24: =IF(A24="","",YEAR(A24)) -> 2026 | F24: Expense | G24: 791 | H24: HDFC Credit Card | I24: Expense | J24: Groceries - Online | K24: =TRUE() -> TRUE | L24: Blinkit groceries
A25: 46236 | C25: =IF(A25="","",TEXT(A25,"dddd")) -> Sunday | D25: =IF(A25="","",TEXT(A25,"MMMM")) -> August | E25: =IF(A25="","",YEAR(A25)) -> 2026 | F25: Refund | G25: 2000 | H25: Expense | I25: HDFC Savings | J25: Reimbursement | K25: =FALSE() -> FALSE | L25: dad returning money for return flight
A26: 46236 | C26: =IF(A26="","",TEXT(A26,"dddd")) -> Sunday | D26: =IF(A26="","",TEXT(A26,"MMMM")) -> August | E26: =IF(A26="","",YEAR(A26)) -> 2026 | F26: Refund | G26: 2000 | H26: Expense | I26: HDFC Savings | J26: Reimbursement | K26: =FALSE() -> FALSE | L26: dad returning money for return flight
A27: 46236 | C27: =IF(A27="","",TEXT(A27,"dddd")) -> Sunday | D27: =IF(A27="","",TEXT(A27,"MMMM")) -> August | E27: =IF(A27="","",YEAR(A27)) -> 2026 | F27: Refund | G27: 3000 | H27: Expense | I27: HDFC Savings | J27: Reimbursement | K27: =FALSE() -> FALSE | L27: dad returning money for return flight
A28: 46236 | C28: =IF(A28="","",TEXT(A28,"dddd")) -> Sunday | D28: =IF(A28="","",TEXT(A28,"MMMM")) -> August | E28: =IF(A28="","",YEAR(A28)) -> 2026 | F28: Refund | G28: 8000 | H28: Expense | I28: HDFC Savings | J28: Reimbursement | K28: =FALSE() -> FALSE | L28: dad returning money for return flight
A29: 46237 | C29: =IF(A29="","",TEXT(A29,"dddd")) -> Monday | D29: =IF(A29="","",TEXT(A29,"MMMM")) -> August | E29: =IF(A29="","",YEAR(A29)) -> 2026 | F29: Expense | G29: 5 | H29: HDFC Savings | I29: Expense | J29: Medical | K29: =TRUE() -> TRUE | L29: Pharmacy
A30: 46237 | C30: =IF(A30="","",TEXT(A30,"dddd")) -> Monday | D30: =IF(A30="","",TEXT(A30,"MMMM")) -> August | E30: =IF(A30="","",YEAR(A30)) -> 2026 | F30: Expense | G30: 20 | H30: HDFC Savings | I30: Expense | J30: Eating outside | K30: =TRUE() -> TRUE | L30: Gokhana food
A31: 46237 | C31: =IF(A31="","",TEXT(A31,"dddd")) -> Monday | D31: =IF(A31="","",TEXT(A31,"MMMM")) -> August | E31: =IF(A31="","",YEAR(A31)) -> 2026 | F31: Expense | G31: 20 | H31: HDFC Savings | I31: Expense | J31: Parking | K31: =TRUE() -> TRUE | L31: Local shop
A32: 46237 | C32: =IF(A32="","",TEXT(A32,"dddd")) -> Monday | D32: =IF(A32="","",TEXT(A32,"MMMM")) -> August | E32: =IF(A32="","",YEAR(A32)) -> 2026 | F32: Expense | G32: 20 | H32: HDFC Savings | I32: Expense | J32: Eating outside | K32: =TRUE() -> TRUE | L32: Local tea snack
A33: 46237 | C33: =IF(A33="","",TEXT(A33,"dddd")) -> Monday | D33: =IF(A33="","",TEXT(A33,"MMMM")) -> August | E33: =IF(A33="","",YEAR(A33)) -> 2026 | F33: Expense | G33: 25 | H33: HDFC Savings | I33: Expense | J33: Eating outside | K33: =TRUE() -> TRUE | L33: Protein Hub
A34: 46237 | C34: =IF(A34="","",TEXT(A34,"dddd")) -> Monday | D34: =IF(A34="","",TEXT(A34,"MMMM")) -> August | E34: =IF(A34="","",YEAR(A34)) -> 2026 | F34: Expense | G34: 33 | H34: HDFC Savings | I34: Expense | J34: Internet / WiFi | K34: =TRUE() -> TRUE | L34: Airtel recharge
A35: 46237 | C35: =IF(A35="","",TEXT(A35,"dddd")) -> Monday | D35: =IF(A35="","",TEXT(A35,"MMMM")) -> August | E35: =IF(A35="","",YEAR(A35)) -> 2026 | F35: Expense | G35: 120 | H35: HDFC Savings | I35: Expense | J35: Eating outside | K35: =TRUE() -> TRUE | L35: Local shop
A36: 46237 | C36: =IF(A36="","",TEXT(A36,"dddd")) -> Monday | D36: =IF(A36="","",TEXT(A36,"MMMM")) -> August | E36: =IF(A36="","",YEAR(A36)) -> 2026 | F36: Expense | G36: 170 | H36: HDFC Credit Card | I36: Expense | J36: Eating outside | K36: =TRUE() -> TRUE | L36: Gokhana food
A37: 46238 | C37: =IF(A37="","",TEXT(A37,"dddd")) -> Tuesday | D37: =IF(A37="","",TEXT(A37,"MMMM")) -> August | E37: =IF(A37="","",YEAR(A37)) -> 2026 | F37: Expense | G37: 18 | H37: HDFC Savings | I37: Expense | J37: Groceries - Physical | K37: =TRUE() -> TRUE | L37: Akshayakalpa milk
A38: 46238 | C38: =IF(A38="","",TEXT(A38,"dddd")) -> Tuesday | D38: =IF(A38="","",TEXT(A38,"MMMM")) -> August | E38: =IF(A38="","",YEAR(A38)) -> 2026 | F38: Expense | G38: 35 | H38: HDFC Savings | I38: Expense | J38: Eating outside | K38: =TRUE() -> TRUE | L38: Local food stall
A39: 46238 | C39: =IF(A39="","",TEXT(A39,"dddd")) -> Tuesday | D39: =IF(A39="","",TEXT(A39,"MMMM")) -> August | E39: =IF(A39="","",YEAR(A39)) -> 2026 | F39: Expense | G39: 135 | H39: HDFC Savings | I39: Expense | J39: Other | K39: =TRUE() -> TRUE | L39: Traffic challan
A40: 46239 | C40: =IF(A40="","",TEXT(A40,"dddd")) -> Wednesday | D40: =IF(A40="","",TEXT(A40,"MMMM")) -> August | E40: =IF(A40="","",YEAR(A40)) -> 2026 | F40: Expense | G40: 20 | H40: HDFC Savings | I40: Expense | J40: Eating outside | K40: =TRUE() -> TRUE | L40: Local tea snack
...

Sheet Monthly Budget
A1: MONTHLY BUDGET
A2: Only the Budget column is manual (yellow). All other figures come from the Ledger.
A4: THIS MONTH
A5: Month | B5: =TEXT(TODAY(),"MMMM YYYY") -> August 2026
A6: Budget | B6: =IFERROR(INDEX($B$20:$B$61,MATCH(DATE(YEAR(TODAY()),MONTH(TODAY()),1),$A$20:$A$61,0)),Configuration!B6) -> 31000
A7: Income / Salary | B7: =SUMIFS(Ledger!$G:$G,Ledger!$D:$D,TEXT(TODAY(),"MMMM"),Ledger!$E:$E,YEAR(TODAY()),Ledger!$F:$F,"Income") -> 83167
A8: Budget Expenses | B8: =SUMIFS(Ledger!$G:$G,Ledger!$D:$D,TEXT(TODAY(),"MMMM"),Ledger!$E:$E,YEAR(TODAY()),Ledger!$F:$F,"Expense",Ledger!$K:$K,TRUE())-SUMIFS(Ledger!$G:$G,Ledger!$D:$D,TEXT(TODAY(),"MMMM"),Ledger!$E:$E,YEAR(TODAY()),Ledger!$F:$F,"Refund",Ledger!$K:$K,TRUE()) -> 24740.33
A9: Remaining Budget | B9: =B6-B8 -> 6259.67
A10: Non-Budget Expenses | B10: =SUMIFS(Ledger!$G:$G,Ledger!$D:$D,TEXT(TODAY(),"MMMM"),Ledger!$E:$E,YEAR(TODAY()),Ledger!$F:$F,"Expense",Ledger!$K:$K,FALSE()) -> 50671
A11: Investments | B11: =SUMIFS(Ledger!$G:$G,Ledger!$D:$D,TEXT(TODAY(),"MMMM"),Ledger!$E:$E,YEAR(TODAY()),Ledger!$F:$F,"Investment") -> 0
A12: EMIs | B12: =SUMIFS(Ledger!$G:$G,Ledger!$D:$D,TEXT(TODAY(),"MMMM"),Ledger!$E:$E,YEAR(TODAY()),Ledger!$J:$J,"EMIs") -> 0
A13: Rent | B13: =SUMIFS(Ledger!$G:$G,Ledger!$D:$D,TEXT(TODAY(),"MMMM"),Ledger!$E:$E,YEAR(TODAY()),Ledger!$J:$J,"Rent") -> 10800
A14: CC Payments | B14: =SUMIFS(Ledger!$G:$G,Ledger!$D:$D,TEXT(TODAY(),"MMMM"),Ledger!$E:$E,YEAR(TODAY()),Ledger!$F:$F,"Credit Card Payment") -> 11723.51
A15: Est. Savings (Income − outflows) | B15: =B7-B8-B10-B11 -> 7755.67
A16: Budget used % | B16: =IF(B6=0,0,B8/B6) -> 0.79807516
A18: MONTH-BY-MONTH — only Budget (col B) is editable
A19: Month Start | B19: Budget | C19: Income | D19: Budget Expenses | E19: Remaining | F19: Non-Budget Exp | G19: Investments | H19: EMIs | I19: Rent | J19: CC Payments | K19: Est. Savings | L19: Label
A20: 46204 | B20: 31000 | C20: =SUMIFS(Ledger!$G:$G,Ledger!$D:$D,TEXT(A20,"MMMM"),Ledger!$E:$E,YEAR(A20),Ledger!$F:$F,"Income") -> 0 | D20: =SUMIFS(Ledger!$G:$G,Ledger!$D:$D,TEXT(A20,"MMMM"),Ledger!$E:$E,YEAR(A20),Ledger!$F:$F,"Expense",Ledger!$K:$K,TRUE())-SUMIFS(Ledger!$G:$G,Ledger!$D:$D,TEXT(A20,"MMMM"),Ledger!$E:$E,YEAR(A20),Ledger!$F:$F,"Refund",Ledger!$K:$K,TRUE()) -> 3795.04 | E20: =B20-D20 -> 27204.96 | F20: =SUMIFS(Ledger!$G:$G,Ledger!$D:$D,TEXT(A20,"MMMM"),Ledger!$E:$E,YEAR(A20),Ledger!$F:$F,"Expense",Ledger!$K:$K,FALSE()) -> 0 | G20: =SUMIFS(Ledger!$G:$G,Ledger!$D:$D,TEXT(A20,"MMMM"),Ledger!$E:$E,YEAR(A20),Ledger!$F:$F,"Investment") -> 0 | H20: =SUMIFS(Ledger!$G:$G,Ledger!$D:$D,TEXT(A20,"MMMM"),Ledger!$E:$E,YEAR(A20),Ledger!$J:$J,"EMIs") -> 0 | I20: =SUMIFS(Ledger!$G:$G,Ledger!$D:$D,TEXT(A20,"MMMM"),Ledger!$E:$E,YEAR(A20),Ledger!$J:$J,"Rent") -> 0 | J20: =SUMIFS(Ledger!$G:$G,Ledger!$D:$D,TEXT(A20,"MMMM"),Ledger!$E:$E,YEAR(A20),Ledger!$F:$F,"Credit Card Payment") -> 0 | K20: =C20-D20-F20-G20 -> -3795.04 | L20: =TEXT(A20,"MMMM YYYY") -> July 2026
A21: 46235 | B21: 31000 | C21: =SUMIFS(Ledger!$G:$G,Ledger!$D:$D,TEXT(A21,"MMMM"),Ledger!$E:$E,YEAR(A21),Ledger!$F:$F,"Income") -> 83167 | D21: =SUMIFS(Ledger!$G:$G,Ledger!$D:$D,TEXT(A21,"MMMM"),Ledger!$E:$E,YEAR(A21),Ledger!$F:$F,"Expense",Ledger!$K:$K,TRUE())-SUMIFS(Ledger!$G:$G,Ledger!$D:$D,TEXT(A21,"MMMM"),Ledger!$E:$E,YEAR(A21),Ledger!$F:$F,"Refund",Ledger!$K:$K,TRUE()) -> 24740.33 | E21: =B21-D21 -> 6259.67 | F21: =SUMIFS(Ledger!$G:$G,Ledger!$D:$D,TEXT(A21,"MMMM"),Ledger!$E:$E,YEAR(A21),Ledger!$F:$F,"Expense",Ledger!$K:$K,FALSE()) -> 50671 | G21: =SUMIFS(Ledger!$G:$G,Ledger!$D:$D,TEXT(A21,"MMMM"),Ledger!$E:$E,YEAR(A21),Ledger!$F:$F,"Investment") -> 0 | H21: =SUMIFS(Ledger!$G:$G,Ledger!$D:$D,TEXT(A21,"MMMM"),Ledger!$E:$E,YEAR(A21),Ledger!$J:$J,"EMIs") -> 0 | I21: =SUMIFS(Ledger!$G:$G,Ledger!$D:$D,TEXT(A21,"MMMM"),Ledger!$E:$E,YEAR(A21),Ledger!$J:$J,"Rent") -> 10800 | J21: =SUMIFS(Ledger!$G:$G,Ledger!$D:$D,TEXT(A21,"MMMM"),Ledger!$E:$E,YEAR(A21),Ledger!$F:$F,"Credit Card Payment") -> 11723.51 | K21: =C21-D21-F21-G21 -> 7755.67 | L21: =TEXT(A21,"MMMM YYYY") -> August 2026
A22: 46266 | B22: 31000 | C22: =SUMIFS(Ledger!$G:$G,Ledger!$D:$D,TEXT(A22,"MMMM"),Ledger!$E:$E,YEAR(A22),Ledger!$F:$F,"Income") -> 0 | D22: =SUMIFS(Ledger!$G:$G,Ledger!$D:$D,TEXT(A22,"MMMM"),Ledger!$E:$E,YEAR(A22),Ledger!$F:$F,"Expense",Ledger!$K:$K,TRUE())-SUMIFS(Ledger!$G:$G,Ledger!$D:$D,TEXT(A22,"MMMM"),Ledger!$E:$E,YEAR(A22),Ledger!$F:$F,"Refund",Ledger!$K:$K,TRUE()) -> 0 | E22: =B22-D22 -> 31000 | F22: =SUMIFS(Ledger!$G:$G,Ledger!$D:$D,TEXT(A22,"MMMM"),Ledger!$E:$E,YEAR(A22),Ledger!$F:$F,"Expense",Ledger!$K:$K,FALSE()) -> 0 | G22: =SUMIFS(Ledger!$G:$G,Ledger!$D:$D,TEXT(A22,"MMMM"),Ledger!$E:$E,YEAR(A22),Ledger!$F:$F,"Investment") -> 0 | H22: =SUMIFS(Ledger!$G:$G,Ledger!$D:$D,TEXT(A22,"MMMM"),Ledger!$E:$E,YEAR(A22),Ledger!$J:$J,"EMIs") -> 0 | I22: =SUMIFS(Ledger!$G:$G,Ledger!$D:$D,TEXT(A22,"MMMM"),Ledger!$E:$E,YEAR(A22),Ledger!$J:$J,"Rent") -> 0 | J22: =SUMIFS(Ledger!$G:$G,Ledger!$D:$D,TEXT(A22,"MMMM"),Ledger!$E:$E,YEAR(A22),Ledger!$F:$F,"Credit Card Payment") -> 0 | K22: =C22-D22-F22-G22 -> 0 | L22: =TEXT(A22,"MMMM YYYY") -> September 2026
A23: 46296 | B23: 31000 | C23: =SUMIFS(Ledger!$G:$G,Ledger!$D:$D,TEXT(A23,"MMMM"),Ledger!$E:$E,YEAR(A23),Ledger!$F:$F,"Income") -> 0 | D23: =SUMIFS(Ledger!$G:$G,Ledger!$D:$D,TEXT(A23,"MMMM"),Ledger!$E:$E,YEAR(A23),Ledger!$F:$F,"Expense",Ledger!$K:$K,TRUE())-SUMIFS(Ledger!$G:$G,Ledger!$D:$D,TEXT(A23,"MMMM"),Ledger!$E:$E,YEAR(A23),Ledger!$F:$F,"Refund",Ledger!$K:$K,TRUE()) -> 0 | E23: =B23-D23 -> 31000 | F23: =SUMIFS(Ledger!$G:$G,Ledger!$D:$D,TEXT(A23,"MMMM"),Ledger!$E:$E,YEAR(A23),Ledger!$F:$F,"Expense",Ledger!$K:$K,FALSE()) -> 0 | G23: =SUMIFS(Ledger!$G:$G,Ledger!$D:$D,TEXT(A23,"MMMM"),Ledger!$E:$E,YEAR(A23),Ledger!$F:$F,"Investment") -> 0 | H23: =SUMIFS(Ledger!$G:$G,Ledger!$D:$D,TEXT(A23,"MMMM"),Ledger!$E:$E,YEAR(A23),Ledger!$J:$J,"EMIs") -> 0 | I23: =SUMIFS(Ledger!$G:$G,Ledger!$D:$D,TEXT(A23,"MMMM"),Ledger!$E:$E,YEAR(A23),Ledger!$J:$J,"Rent") -> 0 | J23: =SUMIFS(Ledger!$G:$G,Ledger!$D:$D,TEXT(A23,"MMMM"),Ledger!$E:$E,YEAR(A23),Ledger!$F:$F,"Credit Card Payment") -> 0 | K23: =C23-D23-F23-G23 -> 0 | L23: =TEXT(A23,"MMMM YYYY") -> October 2026
A24: 46327 | B24: 31000 | C24: =SUMIFS(Ledger!$G:$G,Ledger!$D:$D,TEXT(A24,"MMMM"),Ledger!$E:$E,YEAR(A24),Ledger!$F:$F,"Income") -> 0 | D24: =SUMIFS(Ledger!$G:$G,Ledger!$D:$D,TEXT(A24,"MMMM"),Ledger!$E:$E,YEAR(A24),Ledger!$F:$F,"Expense",Ledger!$K:$K,TRUE())-SUMIFS(Ledger!$G:$G,Ledger!$D:$D,TEXT(A24,"MMMM"),Ledger!$E:$E,YEAR(A24),Ledger!$F:$F,"Refund",Ledger!$K:$K,TRUE()) -> 0 | E24: =B24-D24 -> 31000 | F24: =SUMIFS(Ledger!$G:$G,Ledger!$D:$D,TEXT(A24,"MMMM"),Ledger!$E:$E,YEAR(A24),Ledger!$F:$F,"Expense",Ledger!$K:$K,FALSE()) -> 0 | G24: =SUMIFS(Ledger!$G:$G,Ledger!$D:$D,TEXT(A24,"MMMM"),Ledger!$E:$E,YEAR(A24),Ledger!$F:$F,"Investment") -> 0 | H24: =SUMIFS(Ledger!$G:$G,Ledger!$D:$D,TEXT(A24,"MMMM"),Ledger!$E:$E,YEAR(A24),Ledger!$J:$J,"EMIs") -> 0 | I24: =SUMIFS(Ledger!$G:$G,Ledger!$D:$D,TEXT(A24,"MMMM"),Ledger!$E:$E,YEAR(A24),Ledger!$J:$J,"Rent") -> 0 | J24: =SUMIFS(Ledger!$G:$G,Ledger!$D:$D,TEXT(A24,"MMMM"),Ledger!$E:$E,YEAR(A24),Ledger!$F:$F,"Credit Card Payment") -> 0 | K24: =C24-D24-F24-G24 -> 0 | L24: =TEXT(A24,"MMMM YYYY") -> November 2026
A25: 46357 | B25: 31000 | C25: =SUMIFS(Ledger!$G:$G,Ledger!$D:$D,TEXT(A25,"MMMM"),Ledger!$E:$E,YEAR(A25),Ledger!$F:$F,"Income") -> 0 | D25: =SUMIFS(Ledger!$G:$G,Ledger!$D:$D,TEXT(A25,"MMMM"),Ledger!$E:$E,YEAR(A25),Ledger!$F:$F,"Expense",Ledger!$K:$K,TRUE())-SUMIFS(Ledger!$G:$G,Ledger!$D:$D,TEXT(A25,"MMMM"),Ledger!$E:$E,YEAR(A25),Ledger!$F:$F,"Refund",Ledger!$K:$K,TRUE()) -> 0 | E25: =B25-D25 -> 31000 | F25: =SUMIFS(Ledger!$G:$G,Ledger!$D:$D,TEXT(A25,"MMMM"),Ledger!$E:$E,YEAR(A25),Ledger!$F:$F,"Expense",Ledger!$K:$K,FALSE()) -> 0 | G25: =SUMIFS(Ledger!$G:$G,Ledger!$D:$D,TEXT(A25,"MMMM"),Ledger!$E:$E,YEAR(A25),Ledger!$F:$F,"Investment") -> 0 | H25: =SUMIFS(Ledger!$G:$G,Ledger!$D:$D,TEXT(A25,"MMMM"),Ledger!$E:$E,YEAR(A25),Ledger!$J:$J,"EMIs") -> 0 | I25: =SUMIFS(Ledger!$G:$G,Ledger!$D:$D,TEXT(A25,"MMMM"),Ledger!$E:$E,YEAR(A25),Ledger!$J:$J,"Rent") -> 0 | J25: =SUMIFS(Ledger!$G:$G,Ledger!$D:$D,TEXT(A25,"MMMM"),Ledger!$E:$E,YEAR(A25),Ledger!$F:$F,"Credit Card Payment") -> 0 | K25: =C25-D25-F25-G25 -> 0 | L25: =TEXT(A25,"MMMM YYYY") -> December 2026
A26: 46388 | B26: 31000 | C26: =SUMIFS(Ledger!$G:$G,Ledger!$D:$D,TEXT(A26,"MMMM"),Ledger!$E:$E,YEAR(A26),Ledger!$F:$F,"Income") -> 0 | D26: =SUMIFS(Ledger!$G:$G,Ledger!$D:$D,TEXT(A26,"MMMM"),Ledger!$E:$E,YEAR(A26),Ledger!$F:$F,"Expense",Ledger!$K:$K,TRUE())-SUMIFS(Ledger!$G:$G,Ledger!$D:$D,TEXT(A26,"MMMM"),Ledger!$E:$E,YEAR(A26),Ledger!$F:$F,"Refund",Ledger!$K:$K,TRUE()) -> 0 | E26: =B26-D26 -> 31000 | F26: =SUMIFS(Ledger!$G:$G,Ledger!$D:$D,TEXT(A26,"MMMM"),Ledger!$E:$E,YEAR(A26),Ledger!$F:$F,"Expense",Ledger!$K:$K,FALSE()) -> 0 | G26: =SUMIFS(Ledger!$G:$G,Ledger!$D:$D,TEXT(A26,"MMMM"),Ledger!$E:$E,YEAR(A26),Ledger!$F:$F,"Investment") -> 0 | H26: =SUMIFS(Ledger!$G:$G,Ledger!$D:$D,TEXT(A26,"MMMM"),Ledger!$E:$E,YEAR(A26),Ledger!$J:$J,"EMIs") -> 0 | I26: =SUMIFS(Ledger!$G:$G,Ledger!$D:$D,TEXT(A26,"MMMM"),Ledger!$E:$E,YEAR(A26),Ledger!$J:$J,"Rent") -> 0 | J26: =SUMIFS(Ledger!$G:$G,Ledger!$D:$D,TEXT(A26,"MMMM"),Ledger!$E:$E,YEAR(A26),Ledger!$F:$F,"Credit Card Payment") -> 0 | K26: =C26-D26-F26-G26 -> 0 | L26: =TEXT(A26,"MMMM YYYY") -> January 2027
A27: 46419 | B27: 31000 | C27: =SUMIFS(Ledger!$G:$G,Ledger!$D:$D,TEXT(A27,"MMMM"),Ledger!$E:$E,YEAR(A27),Ledger!$F:$F,"Income") -> 0 | D27: =SUMIFS(Ledger!$G:$G,Ledger!$D:$D,TEXT(A27,"MMMM"),Ledger!$E:$E,YEAR(A27),Ledger!$F:$F,"Expense",Ledger!$K:$K,TRUE())-SUMIFS(Ledger!$G:$G,Ledger!$D:$D,TEXT(A27,"MMMM"),Ledger!$E:$E,YEAR(A27),Ledger!$F:$F,"Refund",Ledger!$K:$K,TRUE()) -> 0 | E27: =B27-D27 -> 31000 | F27: =SUMIFS(Ledger!$G:$G,Ledger!$D:$D,TEXT(A27,"MMMM"),Ledger!$E:$E,YEAR(A27),Ledger!$F:$F,"Expense",Ledger!$K:$K,FALSE()) -> 0 | G27: =SUMIFS(Ledger!$G:$G,Ledger!$D:$D,TEXT(A27,"MMMM"),Ledger!$E:$E,YEAR(A27),Ledger!$F:$F,"Investment") -> 0 | H27: =SUMIFS(Ledger!$G:$G,Ledger!$D:$D,TEXT(A27,"MMMM"),Ledger!$E:$E,YEAR(A27),Ledger!$J:$J,"EMIs") -> 0 | I27: =SUMIFS(Ledger!$G:$G,Ledger!$D:$D,TEXT(A27,"MMMM"),Ledger!$E:$E,YEAR(A27),Ledger!$J:$J,"Rent") -> 0 | J27: =SUMIFS(Ledger!$G:$G,Ledger!$D:$D,TEXT(A27,"MMMM"),Ledger!$E:$E,YEAR(A27),Ledger!$F:$F,"Credit Card Payment") -> 0 | K27: =C27-D27-F27-G27 -> 0 | L27: =TEXT(A27,"MMMM YYYY") -> February 2027
A28: 46447 | B28: 31000 | C28: =SUMIFS(Ledger!$G:$G,Ledger!$D:$D,TEXT(A28,"MMMM"),Ledger!$E:$E,YEAR(A28),Ledger!$F:$F,"Income") -> 0 | D28: =SUMIFS(Ledger!$G:$G,Ledger!$D:$D,TEXT(A28,"MMMM"),Ledger!$E:$E,YEAR(A28),Ledger!$F:$F,"Expense",Ledger!$K:$K,TRUE())-SUMIFS(Ledger!$G:$G,Ledger!$D:$D,TEXT(A28,"MMMM"),Ledger!$E:$E,YEAR(A28),Ledger!$F:$F,"Refund",Ledger!$K:$K,TRUE()) -> 0 | E28: =B28-D28 -> 31000 | F28: =SUMIFS(Ledger!$G:$G,Ledger!$D:$D,TEXT(A28,"MMMM"),Ledger!$E:$E,YEAR(A28),Ledger!$F:$F,"Expense",Ledger!$K:$K,FALSE()) -> 0 | G28: =SUMIFS(Ledger!$G:$G,Ledger!$D:$D,TEXT(A28,"MMMM"),Ledger!$E:$E,YEAR(A28),Ledger!$F:$F,"Investment") -> 0 | H28: =SUMIFS(Ledger!$G:$G,Ledger!$D:$D,TEXT(A28,"MMMM"),Ledger!$E:$E,YEAR(A28),Ledger!$J:$J,"EMIs") -> 0 | I28: =SUMIFS(Ledger!$G:$G,Ledger!$D:$D,TEXT(A28,"MMMM"),Ledger!$E:$E,YEAR(A28),Ledger!$J:$J,"Rent") -> 0 | J28: =SUMIFS(Ledger!$G:$G,Ledger!$D:$D,TEXT(A28,"MMMM"),Ledger!$E:$E,YEAR(A28),Ledger!$F:$F,"Credit Card Payment") -> 0 | K28: =C28-D28-F28-G28 -> 0 | L28: =TEXT(A28,"MMMM YYYY") -> March 2027
A29: 46478 | B29: 31000 | C29: =SUMIFS(Ledger!$G:$G,Ledger!$D:$D,TEXT(A29,"MMMM"),Ledger!$E:$E,YEAR(A29),Ledger!$F:$F,"Income") -> 0 | D29: =SUMIFS(Ledger!$G:$G,Ledger!$D:$D,TEXT(A29,"MMMM"),Ledger!$E:$E,YEAR(A29),Ledger!$F:$F,"Expense",Ledger!$K:$K,TRUE())-SUMIFS(Ledger!$G:$G,Ledger!$D:$D,TEXT(A29,"MMMM"),Ledger!$E:$E,YEAR(A29),Ledger!$F:$F,"Refund",Ledger!$K:$K,TRUE()) -> 0 | E29: =B29-D29 -> 31000 | F29: =SUMIFS(Ledger!$G:$G,Ledger!$D:$D,TEXT(A29,"MMMM"),Ledger!$E:$E,YEAR(A29),Ledger!$F:$F,"Expense",Ledger!$K:$K,FALSE()) -> 0 | G29: =SUMIFS(Ledger!$G:$G,Ledger!$D:$D,TEXT(A29,"MMMM"),Ledger!$E:$E,YEAR(A29),Ledger!$F:$F,"Investment") -> 0 | H29: =SUMIFS(Ledger!$G:$G,Ledger!$D:$D,TEXT(A29,"MMMM"),Ledger!$E:$E,YEAR(A29),Ledger!$J:$J,"EMIs") -> 0 | I29: =SUMIFS(Ledger!$G:$G,Ledger!$D:$D,TEXT(A29,"MMMM"),Ledger!$E:$E,YEAR(A29),Ledger!$J:$J,"Rent") -> 0 | J29: =SUMIFS(Ledger!$G:$G,Ledger!$D:$D,TEXT(A29,"MMMM"),Ledger!$E:$E,YEAR(A29),Ledger!$F:$F,"Credit Card Payment") -> 0 | K29: =C29-D29-F29-G29 -> 0 | L29: =TEXT(A29,"MMMM YYYY") -> April 2027
A30: 46508 | B30: 31000 | C30: =SUMIFS(Ledger!$G:$G,Ledger!$D:$D,TEXT(A30,"MMMM"),Ledger!$E:$E,YEAR(A30),Ledger!$F:$F,"Income") -> 0 | D30: =SUMIFS(Ledger!$G:$G,Ledger!$D:$D,TEXT(A30,"MMMM"),Ledger!$E:$E,YEAR(A30),Ledger!$F:$F,"Expense",Ledger!$K:$K,TRUE())-SUMIFS(Ledger!$G:$G,Ledger!$D:$D,TEXT(A30,"MMMM"),Ledger!$E:$E,YEAR(A30),Ledger!$F:$F,"Refund",Ledger!$K:$K,TRUE()) -> 0 | E30: =B30-D30 -> 31000 | F30: =SUMIFS(Ledger!$G:$G,Ledger!$D:$D,TEXT(A30,"MMMM"),Ledger!$E:$E,YEAR(A30),Ledger!$F:$F,"Expense",Ledger!$K:$K,FALSE()) -> 0 | G30: =SUMIFS(Ledger!$G:$G,Ledger!$D:$D,TEXT(A30,"MMMM"),Ledger!$E:$E,YEAR(A30),Ledger!$F:$F,"Investment") -> 0 | H30: =SUMIFS(Ledger!$G:$G,Ledger!$D:$D,TEXT(A30,"MMMM"),Ledger!$E:$E,YEAR(A30),Ledger!$J:$J,"EMIs") -> 0 | I30: =SUMIFS(Ledger!$G:$G,Ledger!$D:$D,TEXT(A30,"MMMM"),Ledger!$E:$E,YEAR(A30),Ledger!$J:$J,"Rent") -> 0 | J30: =SUMIFS(Ledger!$G:$G,Ledger!$D:$D,TEXT(A30,"MMMM"),Ledger!$E:$E,YEAR(A30),Ledger!$F:$F,"Credit Card Payment") -> 0 | K30: =C30-D30-F30-G30 -> 0 | L30: =TEXT(A30,"MMMM YYYY") -> May 2027
A31: 46539 | B31: 31000 | C31: =SUMIFS(Ledger!$G:$G,Ledger!$D:$D,TEXT(A31,"MMMM"),Ledger!$E:$E,YEAR(A31),Ledger!$F:$F,"Income") -> 0 | D31: =SUMIFS(Ledger!$G:$G,Ledger!$D:$D,TEXT(A31,"MMMM"),Ledger!$E:$E,YEAR(A31),Ledger!$F:$F,"Expense",Ledger!$K:$K,TRUE())-SUMIFS(Ledger!$G:$G,Ledger!$D:$D,TEXT(A31,"MMMM"),Ledger!$E:$E,YEAR(A31),Ledger!$F:$F,"Refund",Ledger!$K:$K,TRUE()) -> 0 | E31: =B31-D31 -> 31000 | F31: =SUMIFS(Ledger!$G:$G,Ledger!$D:$D,TEXT(A31,"MMMM"),Ledger!$E:$E,YEAR(A31),Ledger!$F:$F,"Expense",Ledger!$K:$K,FALSE()) -> 0 | G31: =SUMIFS(Ledger!$G:$G,Ledger!$D:$D,TEXT(A31,"MMMM"),Ledger!$E:$E,YEAR(A31),Ledger!$F:$F,"Investment") -> 0 | H31: =SUMIFS(Ledger!$G:$G,Ledger!$D:$D,TEXT(A31,"MMMM"),Ledger!$E:$E,YEAR(A31),Ledger!$J:$J,"EMIs") -> 0 | I31: =SUMIFS(Ledger!$G:$G,Ledger!$D:$D,TEXT(A31,"MMMM"),Ledger!$E:$E,YEAR(A31),Ledger!$J:$J,"Rent") -> 0 | J31: =SUMIFS(Ledger!$G:$G,Ledger!$D:$D,TEXT(A31,"MMMM"),Ledger!$E:$E,YEAR(A31),Ledger!$F:$F,"Credit Card Payment") -> 0 | K31: =C31-D31-F31-G31 -> 0 | L31: =TEXT(A31,"MMMM YYYY") -> June 2027
... A61: 47453 | B61: 31000 | C61: =SUMIFS(Ledger!$G:$G,Ledger!$D:$D,TEXT(A61,"MMMM"),Ledger!$E:$E,YEAR(A61),Ledger!$F:$F,"Income") -> 0 | D61: =SUMIFS(Ledger!$G:$G,Ledger!$D:$D,TEXT(A61,"MMMM"),Ledger!$E:$E,YEAR(A61),Ledger!$F:$F,"Expense",Ledger!$K:$K,TRUE())-SUMIFS(Ledger!$G:$G,Ledger!$D:$D,TEXT(A61,"MMMM"),Ledger!$E:$E,YEAR(A61),Ledger!$F:$F,"Refund",Ledger!$K:$K,TRUE()) -> 0 | E61: =B61-D61 -> 31000 | F61: =SUMIFS(Ledger!$G:$G,Ledger!$D:$D,TEXT(A61,"MMMM"),Ledger!$E:$E,YEAR(A61),Ledger!$F:$F,"Expense",Ledger!$K:$K,FALSE()) -> 0 | G61: =SUMIFS(Ledger!$G:$G,Ledger!$D:$D,TEXT(A61,"MMMM"),Ledger!$E:$E,YEAR(A61),Ledger!$F:$F,"Investment") -> 0 | H61: =SUMIFS(Ledger!$G:$G,Ledger!$D:$D,TEXT(A61,"MMMM"),Ledger!$E:$E,YEAR(A61),Ledger!$J:$J,"EMIs") -> 0 | I61: =SUMIFS(Ledger!$G:$G,Ledger!$D:$D,TEXT(A61,"MMMM"),Ledger!$E:$E,YEAR(A61),Ledger!$J:$J,"Rent") -> 0 | J61: =SUMIFS(Ledger!$G:$G,Ledger!$D:$D,TEXT(A61,"MMMM"),Ledger!$E:$E,YEAR(A61),Ledger!$F:$F,"Credit Card Payment") -> 0 | K61: =C61-D61-F61-G61 -> 0 | L61: =TEXT(A61,"MMMM YYYY") -> December 2029

Sheet Reconciliation
A1: ACCOUNT RECONCILIATION
A2: Calculated balance always comes from Opening + Ledger. Enter Actual only when you check your bank/app. If Difference ≠ 0: find the missing txn, or add Type=Adjustment. Never overwrite Calculated.
A4: Account | B4: Type | C4: Calculated | D4: Actual | E4: Difference | F4: Last Reconciled | G4: Notes
A5: =Configuration!A11 -> HDFC Savings | B5: =Configuration!B11 -> Asset | C5: =IF(B5="Liability",Configuration!C11+SUMIF(Ledger!$H:$H,A5,Ledger!$G:$G)-SUMIF(Ledger!$I:$I,A5,Ledger!$G:$G),Configuration!C11+SUMIF(Ledger!$I:$I,A5,Ledger!$G:$G)-SUMIF(Ledger!$H:$H,A5,Ledger!$G:$G)) -> 47649.45 | D5: 47649.45 | E5: =IF(D5="","",D5-C5) -> 0 | F5: 46240 | G5: Bank stmt close Aug 6
A6: =Configuration!A12 -> ICICI Savings | B6: =Configuration!B12 -> Asset | C6: =IF(B6="Liability",Configuration!C12+SUMIF(Ledger!$H:$H,A6,Ledger!$G:$G)-SUMIF(Ledger!$I:$I,A6,Ledger!$G:$G),Configuration!C12+SUMIF(Ledger!$I:$I,A6,Ledger!$G:$G)-SUMIF(Ledger!$H:$H,A6,Ledger!$G:$G)) -> 142.11 | D6: 142.11 | E6: =IF(D6="","",D6-C6) -> 0 | F6: 46240 | G6: No Aug activity
A7: =Configuration!A13 -> Cash | B7: =Configuration!B13 -> Asset | C7: =IF(B7="Liability",Configuration!C13+SUMIF(Ledger!$H:$H,A7,Ledger!$G:$G)-SUMIF(Ledger!$I:$I,A7,Ledger!$G:$G),Configuration!C13+SUMIF(Ledger!$I:$I,A7,Ledger!$G:$G)-SUMIF(Ledger!$H:$H,A7,Ledger!$G:$G)) -> 0 | E7: =IF(D7="","",D7-C7)
A8: =Configuration!A14 -> Wallet | B8: =Configuration!B14 -> Asset | C8: =IF(B8="Liability",Configuration!C14+SUMIF(Ledger!$H:$H,A8,Ledger!$G:$G)-SUMIF(Ledger!$I:$I,A8,Ledger!$G:$G),Configuration!C14+SUMIF(Ledger!$I:$I,A8,Ledger!$G:$G)-SUMIF(Ledger!$H:$H,A8,Ledger!$G:$G)) -> 0 | E8: =IF(D8="","",D8-C8)
A9: =Configuration!A15 -> HDFC Credit Card | B9: =Configuration!B15 -> Liability | C9: =IF(B9="Liability",Configuration!C15+SUMIF(Ledger!$H:$H,A9,Ledger!$G:$G)-SUMIF(Ledger!$I:$I,A9,Ledger!$G:$G),Configuration!C15+SUMIF(Ledger!$I:$I,A9,Ledger!$G:$G)-SUMIF(Ledger!$H:$H,A9,Ledger!$G:$G)) -> 32765.33 | D9: 31665.33 | E9: =IF(D9="","",D9-C9) -> -1100 | F9: 46240 | G9: Approx = Aug CC spends (no prior due in sheet)
A10: =Configuration!A16 -> ICICI Credit Card | B10: =Configuration!B16 -> Liability | C10: =IF(B10="Liability",Configuration!C16+SUMIF(Ledger!$H:$H,A10,Ledger!$G:$G)-SUMIF(Ledger!$I:$I,A10,Ledger!$G:$G),Configuration!C16+SUMIF(Ledger!$I:$I,A10,Ledger!$G:$G)-SUMIF(Ledger!$H:$H,A10,Ledger!$G:$G)) -> 3795.04 | D10: 3795.04 | E10: =IF(D10="","",D10-C10) -> 0 | F10: 46240 | G10: Stmt residual after bill pay + cycle spends
A11: =Configuration!A17 -> FD | B11: =Configuration!B17 -> Asset | C11: =IF(B11="Liability",Configuration!C17+SUMIF(Ledger!$H:$H,A11,Ledger!$G:$G)-SUMIF(Ledger!$I:$I,A11,Ledger!$G:$G),Configuration!C17+SUMIF(Ledger!$I:$I,A11,Ledger!$G:$G)-SUMIF(Ledger!$H:$H,A11,Ledger!$G:$G)) -> 0 | E11: =IF(D11="","",D11-C11)
A12: =Configuration!A18 -> Mutual Fund | B12: =Configuration!B18 -> Asset | C12: =IF(B12="Liability",Configuration!C18+SUMIF(Ledger!$H:$H,A12,Ledger!$G:$G)-SUMIF(Ledger!$I:$I,A12,Ledger!$G:$G),Configuration!C18+SUMIF(Ledger!$I:$I,A12,Ledger!$G:$G)-SUMIF(Ledger!$H:$H,A12,Ledger!$G:$G)) -> 0 | E12: =IF(D12="","",D12-C12)
A13: =Configuration!A19 -> Employer | B13: =Configuration!B19 -> Virtual | C13: =IF(B13="Liability",Configuration!C19+SUMIF(Ledger!$H:$H,A13,Ledger!$G:$G)-SUMIF(Ledger!$I:$I,A13,Ledger!$G:$G),Configuration!C19+SUMIF(Ledger!$I:$I,A13,Ledger!$G:$G)-SUMIF(Ledger!$H:$H,A13,Ledger!$G:$G)) -> -83167 | E13: =IF(D13="","",D13-C13)
A14: =Configuration!A20 -> Expense | B14: =Configuration!B20 -> Virtual | C14: =IF(B14="Liability",Configuration!C20+SUMIF(Ledger!$H:$H,A14,Ledger!$G:$G)-SUMIF(Ledger!$I:$I,A14,Ledger!$G:$G),Configuration!C20+SUMIF(Ledger!$I:$I,A14,Ledger!$G:$G)-SUMIF(Ledger!$H:$H,A14,Ledger!$G:$G)) -> 64206.37 | E14: =IF(D14="","",D14-C14)
A15: =Configuration!A21 -> External | B15: =Configuration!B21 -> Virtual | C15: =IF(B15="Liability",Configuration!C21+SUMIF(Ledger!$H:$H,A15,Ledger!$G:$G)-SUMIF(Ledger!$I:$I,A15,Ledger!$G:$G),Configuration!C21+SUMIF(Ledger!$I:$I,A15,Ledger!$G:$G)-SUMIF(Ledger!$H:$H,A15,Ledger!$G:$G)) -> 0 | E15: =IF(D15="","",D15-C15)
A18: HOW TO FIX A DIFFERENCE
A19: 1. Investigate bank statement / UPI history for the gap.
A20: 2. If you find the missing txn → add it to the Ledger (do not edit Calculated).
A21: 3. If you cannot find it → Ledger: Type=Adjustment, Category=Reconciliation, Notes=explain.
A22: 4. After Ledger update, Calculated should match Actual. Set Last Reconciled = today.
A23: 5. Never type over a balance to "make it right" — that destroys history.

Sheet Configuration
A1: CONFIGURATION
A2: Edit only yellow cells. Everything else is derived from the Ledger. Do not store current balances here — only opening balances and credit limits.
A4: BUDGET DEFAULT
A5: Setting | B5: Value | C5: Notes
A6: Default Monthly Budget (₹) | B6: 31000 | C6: Override per month on Monthly Budget sheet
A7: Monthly Salary (₹) | B7: 83000 | C7: Take-home used for next-month free-to-allocate estimate on dashboards
A8: ACCOUNTS | H8: LEDGER TYPES | I8: TYPE GUIDE
A9: Every ledger entry moves money From Account → To Account. Opening Balance is the starting point only. | H9: Type | I9: Type | J9: From → To pattern
A10: Account | B10: Type | C10: Opening Balance (₹) | D10: Credit Limit (₹) | E10: Include in Net Worth | F10: Notes | H10: Income | I10: Income | J10: From=Employer → To=bank/cash. Budget=FALSE.
A11: HDFC Savings | B11: Asset | C11: 3851.96 | E11: TRUE | F11: Aug-only start (pre-salary book amount; salary row is Income) | H11: Expense | I11: Expense | J11: From=account/card → To=Expense. Budget=TRUE for normal spends.
A12: ICICI Savings | B12: Asset | C12: 142.11 | E12: TRUE | F12: No Aug ICICI sav txs; balance as of end-Jul | H12: Transfer | I12: Transfer | J12: Between your accounts. Budget=FALSE.
A13: Cash | B13: Asset | C13: 0 | E13: TRUE | H13: Credit Card Payment | I13: Credit Card Payment | J13: From=savings → To=credit card. Budget=FALSE.
A14: Wallet | B14: Asset | C14: 0 | E14: TRUE | F14: UPI wallets etc. | H14: Refund | I14: Refund | J14: From=Expense → To=account/card.
A15: HDFC Credit Card | B15: Liability | C15: 0 | D15: 396000 | E15: TRUE | F15: Aug-only: prior due cleared in sheet; due = this cycle spends | H15: Investment | I15: Investment | J15: From=savings → To=FD / Mutual Fund. Budget=FALSE.
A16: ICICI Credit Card | B16: Liability | C16: 11723.51 | D16: 100000 | E16: TRUE | F16: Open = prior bill 11,723.51; +cycle spends − pay → due ≈ 3,795 | H16: Adjustment | I16: Adjustment | J16: Reconciliation catch-up. Keeps ledger as source of truth.
A17: FD | B17: Asset | C17: 0 | E17: TRUE | F17: Fixed deposits
A18: Mutual Fund | B18: Asset | C18: 0 | E18: TRUE | F18: Investments
A19: Employer | B19: Virtual | C19: 0 | E19: FALSE | F19: Counterparty for salary / income
A20: Expense | B20: Virtual | C20: 0 | E20: FALSE | F20: Counterparty for spends
A21: External | B21: Virtual | C21: 0 | E21: FALSE | F21: Outside world / unknown source
A24: CATEGORIES
A25: Add new rows under the list (yellow). Group helps review. Typical Budget? = default hint — override per Ledger entry.
A26: Category | B26: Group | C26: Typical Budget?
A27: Groceries - Online | B27: Food | C27: TRUE
A28: Groceries - Physical | B28: Food | C28: TRUE
A29: Eating outside | B29: Food | C29: TRUE
A30: Food delivery | B30: Food | C30: TRUE
A31: Cafe / Snacks | B31: Food | C31: TRUE
A32: Petrol | B32: Transport | C32: TRUE
A33: Cab / Auto | B33: Transport | C33: TRUE
A34: Metro / Bus | B34: Transport | C34: TRUE
A35: Parking | B35: Transport | C35: TRUE
A36: Vehicle service | B36: Transport | C36: FALSE
A37: House cleaning (UC) | B37: Home | C37: TRUE
... A80: Other | B80: Other | C80: TRUE
A97: RULES
A98: 1. Enter every money movement exactly once in the Ledger. Never edit calculated balances.
A99: 2. From Account / To Account replace Payment Method + Credit Card.
A100: 3. Amount is always positive. Direction is entirely From → To.
A101: 4. Include in Budget = TRUE only for normal monthly spends under the budget cap.
...
